Workbook

Sheet Summary
A1: Buy vs Rent: Cape Town flat
A2: Net worth if you exited at each point (nominal ZAR, after selling costs and CGT). Change assumptions on the Inputs tab.
A4: Year | B4: 1 | C4: 5 | D4: 10 | E4: 15 | F4: 20 | G4: 25
A5: Buy: net worth | B5: =INDEX(Model!$R$2:$R$27,1+1) -> 466246.67 | C5: =INDEX(Model!$R$2:$R$27,5+1) -> 1755129.3 | D5: =INDEX(Model!$R$2:$R$27,10+1) -> 3897892 | E5: =INDEX(Model!$R$2:$R$27,15+1) -> 6582631.4 | F5: =INDEX(Model!$R$2:$R$27,20+1) -> 10870780 | G5: =INDEX(Model!$R$2:$R$27,25+1) -> 16940562
A6: Rent & invest: net worth | B6: =INDEX(Model!$S$2:$S$27,1+1) -> 1105101.1 | C6: =INDEX(Model!$S$2:$S$27,5+1) -> 2205414.4 | D6: =INDEX(Model!$S$2:$S$27,10+1) -> 3752096.6 | E6: =INDEX(Model!$S$2:$S$27,15+1) -> 5484617.5 | F6: =INDEX(Model!$S$2:$S$27,20+1) -> 7238225.6 | G6: =INDEX(Model!$S$2:$S$27,25+1) -> 6226408.8
A7: Buyer ahead / (behind) | B7: =INDEX(Model!$T$2:$T$27,1+1) -> -638854.4 | C7: =INDEX(Model!$T$2:$T$27,5+1) -> -450285.04 | D7: =INDEX(Model!$T$2:$T$27,10+1) -> 145795.45 | E7: =INDEX(Model!$T$2:$T$27,15+1) -> 1098013.9 | F7: =INDEX(Model!$T$2:$T$27,20+1) -> 3632554.5 | G7: =INDEX(Model!$T$2:$T$27,25+1) -> 10714153
A8: Buy: net worth (today's R) | B8: =INDEX(Model!$U$2:$U$27,1+1) -> 446169.07 | C8: =INDEX(Model!$U$2:$U$27,5+1) -> 1408405.4 | D8: =INDEX(Model!$U$2:$U$27,10+1) -> 2509960.6 | E8: =INDEX(Model!$U$2:$U$27,15+1) -> 3401380.2 | F8: =INDEX(Model!$U$2:$U$27,20+1) -> 4507491.4 | G8: =INDEX(Model!$U$2:$U$27,25+1) -> 5636643.3
A9: Rent: net worth (today's R) | B9: =INDEX(Model!$V$2:$V$27,1+1) -> 1057513 | C9: =INDEX(Model!$V$2:$V$27,5+1) -> 1769737.1 | D9: =INDEX(Model!$V$2:$V$27,10+1) -> 2416078.8 | E9: =INDEX(Model!$V$2:$V$27,15+1) -> 2834014 | F9: =INDEX(Model!$V$2:$V$27,20+1) -> 3001278.6 | G9: =INDEX(Model!$V$2:$V$27,25+1) -> 2071716.7
A10: Monthly owner cost vs rent (that year) | B10: =INDEX(Model!$K$2:$K$27,1+1)/12 -> 21809.385 | C10: =INDEX(Model!$K$2:$K$27,5+1)/12 -> 17098.437 | D10: =INDEX(Model!$K$2:$K$27,10+1)/12 -> 9528.1986 | E10: =INDEX(Model!$K$2:$K$27,15+1)/12 -> -454.80785 | F10: =INDEX(Model!$K$2:$K$27,20+1)/12 -> -13602.269 | G10: =INDEX(Model!$K$2:$K$27,25+1)/12 -> -71327.22
A12: Key inputs
A13: Purchase price | B13: =Inputs!$B$6 -> 4500000
A14: Day-one cash (deposit + costs) | B14: =Inputs!$B$15 -> 848394
A15: Monthly bond repayment | B15: =Inputs!$B$20 -> 40434.385
A16: Starting rent | B16: =Inputs!$B$30 -> 26000
A17: Property growth p.a. | B17: =Inputs!$B$34 -> 0.05
A18: Net investment return p.a. | B18: =Inputs!$B$43 -> 0.078
A19: Rent escalation p.a. | B19: =Inputs!$B$31 -> 0.06
A20: Share of savings invested | B20: =Inputs!$B$41 -> 0.75
A22: Break-even year (buyer first ahead) | B22: =IFERROR(INDEX(Model!$A$3:$A$27,MATCH(TRUE(),INDEX(Model!$T$3:$T$27>0,0),0)),"Not within 25y") -> 10

Sheet Inputs
A1: Buy vs Rent: Cape Town flat (all amounts in ZAR, nominal)
A2: Blue = input you can change. Yellow = key assumption. Black = formula. Edit column B only.
A5: Purchase
A6: Purchase price | B6: 4500000 | C6: Midpoint of your R4-5m range.
A7: Deposit (% of price) | B7: 0.1 | C7: 10% is typical for a non-first-time buyer at this price; 100% bonds exist but cost more.
A8: Deposit | B8: =Inputs!$B$6*Inputs!$B$7 -> 450000 | C8: Formula.
A9: Bond amount | B9: =Inputs!$B$6-Inputs!$B$8 -> 4050000 | C9: Formula.
A10: Transfer duty | B10: =VLOOKUP(Inputs!$B$6,Inputs!$A$52:$C$57,2,TRUE())+VLOOKUP(Inputs!$B$6,Inputs!$A$52:$C$57,3,TRUE())*(Inputs!$B$6-VLOOKUP(Inputs!$B$6,Inputs!$A$52:$C$57,1,TRUE())) -> 272356 | C10: Formula off SARS table below (rates effective 1 Mar 2025). Check sars.gov.za for any 2026 bracket changes.
A11: Transfer attorney fees (incl VAT) | B11: 58000 | C11: Estimate from conveyancing fee guideline for ~R4.5m. Get a quote.
A12: Bond registration fees (incl VAT) | B12: 47000 | C12: Estimate for ~R4m bond registration attorney + deeds office.
A13: Bond initiation fee | B13: 6038 | C13: NCA maximum (R5,250 + VAT).
A14: Other (compliance certs, rates clearance, moving) | B14: 15000 | C14: Allowance.
A15: Total cash needed on day one | B15: =Inputs!$B$8+Inputs!$B$10+Inputs!$B$11+Inputs!$B$12+Inputs!$B$13+Inputs!$B$14 -> 848394 | C15: Formula. Renter invests this lump instead.
A17: Bond
A18: Bond interest rate (p.a.) | B18: 0.105 | C18: Approx SA prime. Good credit may get prime -0.25% to -0.5%. Update to current prime.
A19: Bond term (years) | B19: 20 | C19: Standard SA term.
A20: Monthly bond repayment | B20: =PMT(Inputs!$B$18/12,Inputs!$B$19*12,-Inputs!$B$9) -> 40434.385 | C20: Formula.
A22: Ongoing ownership costs (year 1, monthly)
A23: Levies | B23: 3000 | C23: Sectional title flat in a sought-after area; R2.5-5k common. Building insurance usually inside levy.
A24: Municipal rates | B24: 2000 | C24: CoCT: (value - R300k exclusion) x ~0.6% / 12, roughly.
A25: Extra insurance (bond life cover, homeowner's) | B25: 500 | C25: Only the part a renter would not also pay.
A26: Maintenance & special levies (% of value p.a.) | B26: 0.005 | C26: Interior upkeep, appliances, occasional special levy.
A27: Levy / rates / insurance escalation (p.a.) | B27: 0.07 | C27: CoCT rates and levies have tended to run above CPI.
A29: Renting
A30: Monthly rent (year 1) | B30: 26000 | C30: Midpoint of your R22-30k range.
A31: Rent escalation (p.a.) | B31: 0.06 | C31: Cape Town rents have run hot recently (TPN/PayProp ~5-8%); 6% assumes some cooling.
A33: Market returns (conservative)
A34: Property price growth (p.a., nominal) | B34: 0.05 | C34: Conservative. Long-run SA nominal house prices ~5%; prime Cape Town has done better recently but that is not guaranteed to persist.
A35: Investment return, gross (p.a., nominal) | B35: 0.1 | C35: Conservative for a growth/equity-heavy portfolio: ~CPI 4.5% + 5.5% real.
A36: Fund / platform fees (p.a.) | B36: 0.008 | C36: Mix of low-cost ETFs and platform fee.
A37: Annual tax drag (dividend tax, interest) | B37: 0.004 | C37: Outside a TFSA.
A38: CPI inflation (for real values) | B38: 0.045 | C38: SARB target midpoint.
A40: Behaviour (the honest bit)
A41: Share of monthly savings actually invested | B41: 0.75 | C41: You won't invest 100% of the difference. 25% leaks into lifestyle.
A42: Behaviour gap (p.a. return lost) | B42: 0.01 | C42: Selling in drawdowns, buying late. Morningstar 'Mind the Gap' studies find ~1% p.a.
A43: Net investment return used in model | B43: =Inputs!$B$35-Inputs!$B$36-Inputs!$B$37-Inputs!$B$42 -> 0.078 | C43: Formula = gross - fees - tax drag - behaviour gap.
A45: Exit and tax (assume sale at each year-end)
A46: Agent commission + VAT on sale | B46: 0.0575 | C46: 5% + VAT. Negotiable.
A47: Primary residence CGT exclusion | B47: 2000000 | C47: SARS, current.
A48: Effective CGT rate | B48: 0.18 | C48: 40% inclusion x 45% top marginal rate. Use 40% x your marginal rate.
...

Sheet Model
A1: Year | B1: Property value | C1: Bond balance | D1: Bond payments | E1: Levies | F1: Rates | G1: Insurance | H1: Maintenance | I1: Owner cash cost | J1: Rent | K1: Owner cost - rent | L1: Renter: invested | M1: Renter portfolio | N1: Renter cost basis | O1: Buyer: invested | P1: Buyer portfolio | Q1: Buyer cost basis | R1: BUYER net worth | S1: RENTER net worth | T1: Buyer minus renter | U1: Buyer NW (today's R) | V1: Renter NW (today's R)
A2: 0 | B2: =Inputs!$B$6 -> 4500000 | C2: =Inputs!$B$9 -> 4050000 | D2: 0 | E2: 0 | F2: 0 | G2: 0 | H2: 0 | I2: 0 | J2: 0 | K2: 0 | L2: 0 | M2: =Inputs!$B$15 -> 848394 | N2: =M2 -> 848394 | O2: 0 | P2: 0 | Q2: 0 | R2: =B2*(1-Inputs!$B$46)-C2-MAX(0,B2*(1-Inputs!$B$46)-(Inputs!$B$6+Inputs!$B$10+Inputs!$B$11)-Inputs!$B$47)*Inputs!$B$48+P2-MAX(0,P2-Q2)*Inputs!$B$48 -> 191250 | S2: =M2-MAX(0,M2-N2)*Inputs!$B$48 -> 848394 | T2: =R2-S2 -> -657144 | U2: =R2/(1+Inputs!$B$38)^A2 -> 191250 | V2: =S2/(1+Inputs!$B$38)^A2 -> 848394
A3: 1 | B3: =B2*(1+Inputs!$B$34) -> 4725000 | C3: =IF(A3>=Inputs!$B$19,0,MAX(0,-FV(Inputs!$B$18/12,12*A3,-Inputs!$B$20,Inputs!$B$9))) -> 3987065.8 | D3: =IF(A3<=Inputs!$B$19,12*Inputs!$B$20,0) -> 485212.63 | E3: =12*Inputs!$B$23*(1+Inputs!$B$27)^(A3-1) -> 36000 | F3: =12*Inputs!$B$24*(1+Inputs!$B$27)^(A3-1) -> 24000 | G3: =12*Inputs!$B$25*(1+Inputs!$B$27)^(A3-1) -> 6000 | H3: =Inputs!$B$26*B2 -> 22500 | I3: =SUM(D3:H3) -> 573712.63 | J3: =12*Inputs!$B$30*(1+Inputs!$B$31)^(A3-1) -> 312000 | K3: =I3-J3 -> 261712.63 | L3: =IF(K3>0,K3*Inputs!$B$41,K3) -> 196284.47 | M3: =MAX(0,M2*(1+Inputs!$B$43)+L3*(1+Inputs!$B$43)^0.5) -> 1118364.6 | N3: =MAX(0,N2+L3) -> 1044678.5 | O3: =IF(K3<0,-K3*Inputs!$B$41,0) -> 0 | P3: =P2*(1+Inputs!$B$43)+O3*(1+Inputs!$B$43)^0.5 -> 0 | Q3: =Q2+O3 -> 0 | R3: =B3*(1-Inputs!$B$46)-C3-MAX(0,B3*(1-Inputs!$B$46)-(Inputs!$B$6+Inputs!$B$10+Inputs!$B$11)-Inputs!$B$47)*Inputs!$B$48+P3-MAX(0,P3-Q3)*Inputs!$B$48 -> 466246.67 | S3: =M3-MAX(0,M3-N3)*Inputs!$B$48 -> 1105101.1 | T3: =R3-S3 -> -638854.4 | U3: =R3/(1+Inputs!$B$38)^A3 -> 446169.07 | V3: =S3/(1+Inputs!$B$38)^A3 -> 1057513
A4: 2 | B4: =B3*(1+Inputs!$B$34) -> 4961250 | C4: =IF(A4>=Inputs!$B$19,0,MAX(0,-FV(Inputs!$B$18/12,12*A4,-Inputs!$B$20,Inputs!$B$9))) -> 3917196.1 | D4: =IF(A4<=Inputs!$B$19,12*Inputs!$B$20,0) -> 485212.63 | E4: =12*Inputs!$B$23*(1+Inputs!$B$27)^(A4-1) -> 38520 | F4: =12*Inputs!$B$24*(1+Inputs!$B$27)^(A4-1) -> 25680 | G4: =12*Inputs!$B$25*(1+Inputs!$B$27)^(A4-1) -> 6420 | H4: =Inputs!$B$26*B3 -> 23625 | I4: =SUM(D4:H4) -> 579457.63 | J4: =12*Inputs!$B$30*(1+Inputs!$B$31)^(A4-1) -> 330720 | K4: =I4-J4 -> 248737.63 | L4: =IF(K4>0,K4*Inputs!$B$41,K4) -> 186553.22 | M4: =MAX(0,M3*(1+Inputs!$B$43)+L4*(1+Inputs!$B$43)^0.5) -> 1399289.2 | N4: =MAX(0,N3+L4) -> 1231231.7 | O4: =IF(K4<0,-K4*Inputs!$B$41,0) -> 0 | P4: =P3*(1+Inputs!$B$43)+O4*(1+Inputs!$B$43)^0.5 -> 0 | Q4: =Q3+O4 -> 0 | R4: =B4*(1-Inputs!$B$46)-C4-MAX(0,B4*(1-Inputs!$B$46)-(Inputs!$B$6+Inputs!$B$10+Inputs!$B$11)-Inputs!$B$47)*Inputs!$B$48+P4-MAX(0,P4-Q4)*Inputs!$B$48 -> 758782.03 | S4: =M4-MAX(0,M4-N4)*Inputs!$B$48 -> 1369038.9 | T4: =R4-S4 -> -610256.82 | U4: =R4/(1+Inputs!$B$38)^A4 -> 694839.44 | V4: =S4/(1+Inputs!$B$38)^A4 -> 1253669.9
A5: 3 | B5: =B4*(1+Inputs!$B$34) -> 5209312.5 | C5: =IF(A5>=Inputs!$B$19,0,MAX(0,-FV(Inputs!$B$18/12,12*A5,-Inputs!$B$20,Inputs!$B$9))) -> 3839626.5 | D5: =IF(A5<=Inputs!$B$19,12*Inputs!$B$20,0) -> 485212.63 | E5: =12*Inputs!$B$23*(1+Inputs!$B$27)^(A5-1) -> 41216.4 | F5: =12*Inputs!$B$24*(1+Inputs!$B$27)^(A5-1) -> 27477.6 | G5: =12*Inputs!$B$25*(1+Inputs!$B$27)^(A5-1) -> 6869.4 | H5: =Inputs!$B$26*B4 -> 24806.25 | I5: =SUM(D5:H5) -> 585582.28 | J5: =12*Inputs!$B$30*(1+Inputs!$B$31)^(A5-1) -> 350563.2 | K5: =I5-J5 -> 235019.08 | L5: =IF(K5>0,K5*Inputs!$B$41,K5) -> 176264.31 | M5: =MAX(0,M4*(1+Inputs!$B$43)+L5*(1+Inputs!$B$43)^0.5) -> 1691443.3 | N5: =MAX(0,N4+L5) -> 1407496 | O5: =IF(K5<0,-K5*Inputs!$B$41,0) -> 0 | P5: =P4*(1+Inputs!$B$43)+O5*(1+Inputs!$B$43)^0.5 -> 0 | Q5: =Q4+O5 -> 0 | R5: =B5*(1-Inputs!$B$46)-C5-MAX(0,B5*(1-Inputs!$B$46)-(Inputs!$B$6+Inputs!$B$10+Inputs!$B$11)-Inputs!$B$47)*Inputs!$B$48+P5-MAX(0,P5-Q5)*Inputs!$B$48 -> 1070150.6 | S5: =M5-MAX(0,M5-N5)*Inputs!$B$48 -> 1640332.8 | T5: =R5-S5 -> -570182.24 | U5: =R5/(1+Inputs!$B$38)^A5 -> 937769.3 | V5: =S5/(1+Inputs!$B$38)^A5 -> 1437418.1
A6: 4 | B6: =B5*(1+Inputs!$B$34) -> 5469778.1 | C6: =IF(A6>=Inputs!$B$19,0,MAX(0,-FV(Inputs!$B$18/12,12*A6,-Inputs!$B$20,Inputs!$B$9))) -> 3753508.4 | D6: =IF(A6<=Inputs!$B$19,12*Inputs!$B$20,0) -> 485212.63 | E6: =12*Inputs!$B$23*(1+Inputs!$B$27)^(A6-1) -> 44101.548 | F6: =12*Inputs!$B$24*(1+Inputs!$B$27)^(A6-1) -> 29401.032 | G6: =12*Inputs!$B$25*(1+Inputs!$B$27)^(A6-1) -> 7350.258 | H6: =Inputs!$B$26*B5 -> 26046.562 | I6: =SUM(D6:H6) -> 592112.03 | J6: =12*Inputs!$B$30*(1+Inputs!$B$31)^(A6-1) -> 371596.99 | K6: =I6-J6 -> 220515.03 | L6: =IF(K6>0,K6*Inputs!$B$41,K6) -> 165386.28 | M6: =MAX(0,M5*(1+Inputs!$B$43)+L6*(1+Inputs!$B$43)^0.5) -> 1995091.1 | N6: =MAX(0,N5+L6) -> 1572882.3 | O6: =IF(K6<0,-K6*Inputs!$B$41,0) -> 0 | P6: =P5*(1+Inputs!$B$43)+O6*(1+Inputs!$B$43)^0.5 -> 0 | Q6: =Q5+O6 -> 0 | R6: =B6*(1-Inputs!$B$46)-C6-MAX(0,B6*(1-Inputs!$B$46)-(Inputs!$B$6+Inputs!$B$10+Inputs!$B$11)-Inputs!$B$47)*Inputs!$B$48+P6-MAX(0,P6-Q6)*Inputs!$B$48 -> 1401757.5 | S6: =M6-MAX(0,M6-N6)*Inputs!$B$48 -> 1919093.5 | T6: =R6-S6 -> -517336.07 | U6: =R6/(1+Inputs!$B$38)^A6 -> 1175459.6 | V6: =S6/(1+Inputs!$B$38)^A6 -> 1609277.7
A7: 5 | B7: =B6*(1+Inputs!$B$34) -> 5743267 | C7: =IF(A7>=Inputs!$B$19,0,MAX(0,-FV(Inputs!$B$18/12,12*A7,-Inputs!$B$20,Inputs!$B$9))) -> 3657899.8 | D7: =IF(A7<=Inputs!$B$19,12*Inputs!$B$20,0) -> 485212.63 | E7: =12*Inputs!$B$23*(1+Inputs!$B$27)^(A7-1) -> 47188.656 | F7: =12*Inputs!$B$24*(1+Inputs!$B$27)^(A7-1) -> 31459.104 | G7: =12*Inputs!$B$25*(1+Inputs!$B$27)^(A7-1) -> 7864.7761 | H7: =Inputs!$B$26*B6 -> 27348.891 | I7: =SUM(D7:H7) -> 599074.05 | J7: =12*Inputs!$B$30*(1+Inputs!$B$31)^(A7-1) -> 393892.81 | K7: =I7-J7 -> 205181.24 | L7: =IF(K7>0,K7*Inputs!$B$41,K7) -> 153885.93 | M7: =MAX(0,M6*(1+Inputs!$B$43)+L7*(1+Inputs!$B$43)^0.5) -> 2310483.1 | N7: =MAX(0,N6+L7) -> 1726768.2 | O7: =IF(K7<0,-K7*Inputs!$B$41,0) -> 0 | P7: =P6*(1+Inputs!$B$43)+O7*(1+Inputs!$B$43)^0.5 -> 0 | Q7: =Q6+O7 -> 0 | R7: =B7*(1-Inputs!$B$46)-C7-MAX(0,B7*(1-Inputs!$B$46)-(Inputs!$B$6+Inputs!$B$10+Inputs!$B$11)-Inputs!$B$47)*Inputs!$B$48+P7-MAX(0,P7-Q7)*Inputs!$B$48 -> 1755129.3 | S7: =M7-MAX(0,M7-N7)*Inputs!$B$48 -> 2205414.4 | T7: =R7-S7 -> -450285.04 | U7: =R7/(1+Inputs!$B$38)^A7 -> 1408405.4 | V7: =S7/(1+Inputs!$B$38)^A7 -> 1769737.1
A8: 6 | B8: =B7*(1+Inputs!$B$34) -> 6030430.4 | C8: =IF(A8>=Inputs!$B$19,0,MAX(0,-FV(Inputs!$B$18/12,12*A8,-Inputs!$B$20,Inputs!$B$9))) -> 3551754.9 | D8: =IF(A8<=Inputs!$B$19,12*Inputs!$B$20,0) -> 485212.63 | E8: =12*Inputs!$B$23*(1+Inputs!$B$27)^(A8-1) -> 50491.862 | F8: =12*Inputs!$B$24*(1+Inputs!$B$27)^(A8-1) -> 33661.242 | G8: =12*Inputs!$B$25*(1+Inputs!$B$27)^(A8-1) -> 8415.3104 | H8: =Inputs!$B$26*B7 -> 28716.335 | I8: =SUM(D8:H8) -> 606497.37 | J8: =12*Inputs!$B$30*(1+Inputs!$B$31)^(A8-1) -> 417526.38 | K8: =I8-J8 -> 188970.99 | L8: =IF(K8>0,K8*Inputs!$B$41,K8) -> 141728.25 | M8: =MAX(0,M7*(1+Inputs!$B$43)+L8*(1+Inputs!$B$43)^0.5) -> 2637852.6 | N8: =MAX(0,N7+L8) -> 1868496.4 | O8: =IF(K8<0,-K8*Inputs!$B$41,0) -> 0 | P8: =P7*(1+Inputs!$B$43)+O8*(1+Inputs!$B$43)^0.5 -> 0 | Q8: =Q7+O8 -> 0 | R8: =B8*(1-Inputs!$B$46)-C8-MAX(0,B8*(1-Inputs!$B$46)-(Inputs!$B$6+Inputs!$B$10+Inputs!$B$11)-Inputs!$B$47)*Inputs!$B$48+P8-MAX(0,P8-Q8)*Inputs!$B$48 -> 2131925.8 | S8: =M8-MAX(0,M8-N8)*Inputs!$B$48 -> 2499368.5 | T8: =R8-S8 -> -367442.73 | U8: =R8/(1+Inputs!$B$38)^A8 -> 1637096.7 | V8: =S8/(1+Inputs!$B$38)^A8 -> 1919254.4
A9: 7 | B9: =B8*(1+Inputs!$B$34) -> 6331951.9 | C9: =IF(A9>=Inputs!$B$19,0,MAX(0,-FV(Inputs!$B$18/12,12*A9,-Inputs!$B$20,Inputs!$B$9))) -> 3433912.4 | D9: =IF(A9<=Inputs!$B$19,12*Inputs!$B$20,0) -> 485212.63 | E9: =12*Inputs!$B$23*(1+Inputs!$B$27)^(A9-1) -> 54026.293 | F9: =12*Inputs!$B$24*(1+Inputs!$B$27)^(A9-1) -> 36017.528 | G9: =12*Inputs!$B$25*(1+Inputs!$B$27)^(A9-1) -> 9004.3821 | H9: =Inputs!$B$26*B8 -> 30152.152 | I9: =SUM(D9:H9) -> 614412.98 | J9: =12*Inputs!$B$30*(1+Inputs!$B$31)^(A9-1) -> 442577.96 | K9: =I9-J9 -> 171835.02 | L9: =IF(K9>0,K9*Inputs!$B$41,K9) -> 128876.26 | M9: =MAX(0,M8*(1+Inputs!$B$43)+L9*(1+Inputs!$B$43)^0.5) -> 2977413.2 | N9: =MAX(0,N8+L9) -> 1997372.7 | O9: =IF(K9<0,-K9*Inputs!$B$41,0) -> 0 | P9: =P8*(1+Inputs!$B$43)+O9*(1+Inputs!$B$43)^0.5 -> 0 | Q9: =Q8+O9 -> 0 | R9: =B9*(1-Inputs!$B$46)-C9-MAX(0,B9*(1-Inputs!$B$46)-(Inputs!$B$6+Inputs!$B$10+Inputs!$B$11)-Inputs!$B$47)*Inputs!$B$48+P9-MAX(0,P9-Q9)*Inputs!$B$48 -> 2533952.3 | S9: =M9-MAX(0,M9-N9)*Inputs!$B$48 -> 2801005.9 | T9: =R9-S9 -> -267053.59 | U9: =R9/(1+Inputs!$B$38)^A9 -> 1862020.3 | V9: =S9/(1+Inputs!$B$38)^A9 -> 2058258.8
A10: 8 | B10: =B9*(1+Inputs!$B$34) -> 6648549.5 | C10: =IF(A10>=Inputs!$B$19,0,MAX(0,-FV(Inputs!$B$18/12,12*A10,-Inputs!$B$20,Inputs!$B$9))) -> 3303083.2 | D10: =IF(A10<=Inputs!$B$19,12*Inputs!$B$20,0) -> 485212.63 | E10: =12*Inputs!$B$23*(1+Inputs!$B$27)^(A10-1) -> 57808.133 | F10: =12*Inputs!$B$24*(1+Inputs!$B$27)^(A10-1) -> 38538.755 | G10: =12*Inputs!$B$25*(1+Inputs!$B$27)^(A10-1) -> 9634.6889 | H10: =Inputs!$B$26*B9 -> 31659.76 | I10: =SUM(D10:H10) -> 622853.96 | J10: =12*Inputs!$B$30*(1+Inputs!$B$31)^(A10-1) -> 469132.64 | K10: =I10-J10 -> 153721.32 | L10: =IF(K10>0,K10*Inputs!$B$41,K10) -> 115290.99 | M10: =MAX(0,M9*(1+Inputs!$B$43)+L10*(1+Inputs!$B$43)^0.5) -> 3329354.3 | N10: =MAX(0,N9+L10) -> 2112663.7 | O10: =IF(K10<0,-K10*Inputs!$B$41,0) -> 0 | P10: =P9*(1+Inputs!$B$43)+O10*(1+Inputs!$B$43)^0.5 -> 0 | Q10: =Q9+O10 -> 0 | R10: =B10*(1-Inputs!$B$46)-C10-MAX(0,B10*(1-Inputs!$B$46)-(Inputs!$B$6+Inputs!$B$10+Inputs!$B$11)-Inputs!$B$47)*Inputs!$B$48+P10-MAX(0,P10-Q10)*Inputs!$B$48 -> 2963174.7 | S10: =M10-MAX(0,M10-N10)*Inputs!$B$48 -> 3110350 | T10: =R10-S10 -> -147175.32 | U10: =R10/(1+Inputs!$B$38)^A10 -> 2083660.4 | V10: =S10/(1+Inputs!$B$38)^A10 -> 2187151.9
A11: 9 | B11: =B10*(1+Inputs!$B$34) -> 6980977 | C11: =IF(A11>=Inputs!$B$19,0,MAX(0,-FV(Inputs!$B$18/12,12*A11,-Inputs!$B$20,Inputs!$B$9))) -> 3157836.2 | D11: =IF(A11<=Inputs!$B$19,12*Inputs!$B$20,0) -> 485212.63 | E11: =12*Inputs!$B$23*(1+Inputs!$B$27)^(A11-1) -> 61854.702 | F11: =12*Inputs!$B$24*(1+Inputs!$B$27)^(A11-1) -> 41236.468 | G11: =12*Inputs!$B$25*(1+Inputs!$B$27)^(A11-1) -> 10309.117 | H11: =Inputs!$B$26*B10 -> 33242.747 | I11: =SUM(D11:H11) -> 631855.66 | J11: =12*Inputs!$B$30*(1+Inputs!$B$31)^(A11-1) -> 497280.6 | K11: =I11-J11 -> 134575.06 | L11: =IF(K11>0,K11*Inputs!$B$41,K11) -> 100931.3 | M11: =MAX(0,M10*(1+Inputs!$B$43)+L11*(1+Inputs!$B$43)^0.5) -> 3693837.7 | N11: =MAX(0,N10+L11) -> 2213595 | O11: =IF(K11<0,-K11*Inputs!$B$41,0) -> 0 | P11: =P10*(1+Inputs!$B$43)+O11*(1+Inputs!$B$43)^0.5 -> 0 | Q11: =Q10+O11 -> 0 | R11: =B11*(1-Inputs!$B$46)-C11-MAX(0,B11*(1-Inputs!$B$46)-(Inputs!$B$6+Inputs!$B$10+Inputs!$B$11)-Inputs!$B$47)*Inputs!$B$48+P11-MAX(0,P11-Q11)*Inputs!$B$48 -> 3421734.6 | S11: =M11-MAX(0,M11-N11)*Inputs!$B$48 -> 3427394 | T11: =R11-S11 -> -5659.4299 | U11: =R11/(1+Inputs!$B$38)^A11 -> 2302500.3 | V11: =S11/(1+Inputs!$B$38)^A11 -> 2306308.6
A12: 10 | B12: =B11*(1+Inputs!$B$34) -> 7330025.8 | C12: =IF(A12>=Inputs!$B$19,0,MAX(0,-FV(Inputs!$B$18/12,12*A12,-Inputs!$B$20,Inputs!$B$9))) -> 2996582.5 | D12: =IF(A12<=Inputs!$B$19,12*Inputs!$B$20,0) -> 485212.63 | E12: =12*Inputs!$B$23*(1+Inputs!$B$27)^(A12-1) -> 66184.532 | F12: =12*Inputs!$B$24*(1+Inputs!$B$27)^(A12-1) -> 44123.021 | G12: =12*Inputs!$B$25*(1+Inputs!$B$27)^(A12-1) -> 11030.755 | H12: =Inputs!$B$26*B11 -> 34904.885 | I12: =SUM(D12:H12) -> 641455.82 | J12: =12*Inputs!$B$30*(1+Inputs!$B$31)^(A12-1) -> 527117.44 | K12: =I12-J12 -> 114338.38 | L12: =IF(K12>0,K12*Inputs!$B$41,K12) -> 85753.787 | M12: =MAX(0,M11*(1+Inputs!$B$43)+L12*(1+Inputs!$B$43)^0.5) -> 4070992.4 | N12: =MAX(0,N11+L12) -> 2299348.8 | O12: =IF(K12<0,-K12*Inputs!$B$41,0) -> 0 | P12: =P11*(1+Inputs!$B$43)+O12*(1+Inputs!$B$43)^0.5 -> 0 | Q12: =Q11+O12 -> 0 | R12: =B12*(1-Inputs!$B$46)-C12-MAX(0,B12*(1-Inputs!$B$46)-(Inputs!$B$6+Inputs!$B$10+Inputs!$B$11)-Inputs!$B$47)*Inputs!$B$48+P12-MAX(0,P12-Q12)*Inputs!$B$48 -> 3897892 | S12: =M12-MAX(0,M12-N12)*Inputs!$B$48 -> 3752096.6 | T12: =R12-S12 -> 145795.45 | U12: =R12/(1+Inputs!$B$38)^A12 -> 2509960.6 | V12: =S12/(1+Inputs!$B$38)^A12 -> 2416078.8
A13: 11 | B13: =B12*(1+Inputs!$B$34) -> 7696527.1 | C13: =IF(A13>=Inputs!$B$19,0,MAX(0,-FV(Inputs!$B$18/12,12*A13,-Inputs!$B$20,Inputs!$B$9))) -> 2817558.1 | D13: =IF(A13<=Inputs!$B$19,12*Inputs!$B$20,0) -> 485212.63 | E13: =12*Inputs!$B$23*(1+Inputs!$B$27)^(A13-1) -> 70817.449 | F13: =12*Inputs!$B$24*(1+Inputs!$B$27)^(A13-1) -> 47211.633 | G13: =12*Inputs!$B$25*(1+Inputs!$B$27)^(A13-1) -> 11802.908 | H13: =Inputs!$B$26*B12 -> 36650.129 | I13: =SUM(D13:H13) -> 651694.74 | J13: =12*Inputs!$B$30*(1+Inputs!$B$31)^(A13-1) -> 558744.48 | K13: =I13-J13 -> 92950.262 | L13: =IF(K13>0,K13*Inputs!$B$41,K13) -> 69712.697 | M13: =MAX(0,M12*(1+Inputs!$B$43)+L13*(1+Inputs!$B$43)^0.5) -> 4460910.3 | N13: =MAX(0,N12+L13) -> 2369061.5 | O13: =IF(K13<0,-K13*Inputs!$B$41,0) -> 0 | P13: =P12*(1+Inputs!$B$43)+O13*(1+Inputs!$B$43)^0.5 -> 0 | Q13: =Q12+O13 -> 0 | R13: =B13*(1-Inputs!$B$46)-C13-MAX(0,B13*(1-Inputs!$B$46)-(Inputs!$B$6+Inputs!$B$10+Inputs!$B$11)-Inputs!$B$47)*Inputs!$B$48+P13-MAX(0,P13-Q13)*Inputs!$B$48 -> 4360166.9 | S13: =M13-MAX(0,M13-N13)*Inputs!$B$48 -> 4084377.5 | T13: =R13-S13 -> 275789.45 | U13: =R13/(1+Inputs!$B$38)^A13 -> 2686729.4 | V13: =S13/(1+Inputs!$B$38)^A13 -> 2516788.3
A14: 12 | B14: =B13*(1+Inputs!$B$34) -> 8081353.5 | C14: =IF(A14>=Inputs!$B$19,0,MAX(0,-FV(Inputs!$B$18/12,12*A14,-Inputs!$B$20,Inputs!$B$9))) -> 2618804.6 | D14: =IF(A14<=Inputs!$B$19,12*Inputs!$B$20,0) -> 485212.63 | E14: =12*Inputs!$B$23*(1+Inputs!$B$27)^(A14-1) -> 75774.67 | F14: =12*Inputs!$B$24*(1+Inputs!$B$27)^(A14-1) -> 50516.447 | G14: =12*Inputs!$B$25*(1+Inputs!$B$27)^(A14-1) -> 12629.112 | H14: =Inputs!$B$26*B13 -> 38482.636 | I14: =SUM(D14:H14) -> 662615.49 | J14: =12*Inputs!$B$30*(1+Inputs!$B$31)^(A14-1) -> 592269.15 | K14: =I14-J14 -> 70346.339 | L14: =IF(K14>0,K14*Inputs!$B$41,K14) -> 52759.754 | M14: =MAX(0,M13*(1+Inputs!$B$43)+L14*(1+Inputs!$B$43)^0.5) -> 4863640 | N14: =MAX(0,N13+L14) -> 2421821.2 | O14: =IF(K14<0,-K14*Inputs!$B$41,0) -> 0 | P14: =P13*(1+Inputs!$B$43)+O14*(1+Inputs!$B$43)^0.5 -> 0 | Q14: =Q13+O14 -> 0 | R14: =B14*(1-Inputs!$B$46)-C14-MAX(0,B14*(1-Inputs!$B$46)-(Inputs!$B$6+Inputs!$B$10+Inputs!$B$11)-Inputs!$B$47)*Inputs!$B$48+P14-MAX(0,P14-Q14)*Inputs!$B$48 -> 4856333.5 | S14: =M14-MAX(0,M14-N14)*Inputs!$B$48 -> 4424112.6 | T14: =R14-S14 -> 432220.87 | U14: =R14/(1+Inputs!$B$38)^A14 -> 2863604.4 | V14: =S14/(1+Inputs!$B$38)^A14 -> 2608739.4
... A27: 25 | B27: =B26*(1+Inputs!$B$34) -> 15238597 | C27: =IF(A27>=Inputs!$B$19,0,MAX(0,-FV(Inputs!$B$18/12,12*A27,-Inputs!$B$20,Inputs!$B$9))) -> 0 | D27: =IF(A27<=Inputs!$B$19,12*Inputs!$B$20,0) -> 0 | E27: =12*Inputs!$B$23*(1+Inputs!$B$27)^(A27-1) -> 182605.21 | F27: =12*Inputs!$B$24*(1+Inputs!$B$27)^(A27-1) -> 121736.81 | G27: =12*Inputs!$B$25*(1+Inputs!$B$27)^(A27-1) -> 30434.202 | H27: =Inputs!$B$26*B26 -> 72564.749 | I27: =SUM(D27:H27) -> 407340.97 | J27: =12*Inputs!$B$30*(1+Inputs!$B$31)^(A27-1) -> 1263267.6 | K27: =I27-J27 -> -855926.64 | L27: =IF(K27>0,K27*Inputs!$B$41,K27) -> -855926.64 | M27: =MAX(0,M26*(1+Inputs!$B$43)+L27*(1+Inputs!$B$43)^0.5) -> 7593181.4 | N27: =MAX(0,N26+L27) -> 0 | O27: =IF(K27<0,-K27*Inputs!$B$41,0) -> 641944.98 | P27: =P26*(1+Inputs!$B$43)+O27*(1+Inputs!$B$43)^0.5 -> 4084507.1 | Q27: =Q26+O27 -> 3248067.5 | R27: =B27*(1-Inputs!$B$46)-C27-MAX(0,B27*(1-Inputs!$B$46)-(Inputs!$B$6+Inputs!$B$10+Inputs!$B$11)-Inputs!$B$47)*Inputs!$B$48+P27-MAX(0,P27-Q27)*Inputs!$B$48 -> 16940562 | S27: =M27-MAX(0,M27-N27)*Inputs!$B$48 -> 6226408.8 | T27: =R27-S27 -> 10714153 | U27: =R27/(1+Inputs!$B$38)^A27 -> 5636643.3 | V27: =S27/(1+Inputs!$B$38)^A27 -> 2071716.7
A29: Notes
A30: Net worth = what you'd walk away with if you sold/liquidated at that year-end, after agent fees, bond settlement and CGT.
A31: Renter invests the day-one cash (deposit + fees) in full, then only the 'disc' share of each year's monthly saving.
A32: Once rent overtakes the owner's costs, the renter funds the full shortfall from the portfolio, and the owner invests the disciplined share of their saving.
A33: Contributions assumed mid-year. Cost basis is a simplification (net contributions). Both sides held outside a TFSA.
